Workbook

Sheet Assumptions
A1: Europa-Park Istanbul — Key Assumptions
A2: All monetary values in €M (millions of euros)
A3: GENERAL
A4: Construction start year | B4: 2026
A5: Park opening year | B5: 2028
A6: Projection end year | B6: 2033
A8: REVENUE ASSUMPTIONS
A9: Target annual visitors (millions) | B9: 3.5 | C9: At full ramp-up
A10: Ramp-up Year 1 (2028) — % of target | B10: 0.5
A11: Ramp-up Year 2 (2029) | B11: 0.65
A12: Ramp-up Year 3 (2030) | B12: 0.8
A13: Ramp-up Year 4 (2031) | B13: 0.9
A14: Ramp-up Year 5 (2032) | B14: 0.95
A15: Ramp-up Year 6 (2033) | B15: 1
A16: Average ticket price (€) | B16: 42 | C16: Blended adult/child/group
A17: Per capita in-park spend (€) | B17: 28 | C17: F&B + merchandise + other
A18: Hotel avg nightly rate (€) | B18: 130
A19: Number of hotel rooms | B19: 2000
A20: Hotel occupancy rate | B20: 0.65
A21: Annual price escalation | B21: 0.03
A23: COST ASSUMPTIONS
A24: COGS as % of revenue | B24: 0.3 | C24: F&B supplies, ride ops, merch cost
A25: Operating expenses as % of revenue | B25: 0.25 | C25: Excl. depreciation, HR & marketing shown separately
A26: Annual OpEx efficiency gain | B26: 0.005 | C26: Slight margin improvement over time
A28: INVESTMENT (€M)
A29: Total initial investment | B29: 1000
A30: Land acquisition | B30: 120 | C30: Not depreciated
A31: Construction & infrastructure | B31: 350
A32: Rides & attractions | B32: 380
A33: Hotels (2,000 rooms) | B33: 100
A34: Pre-opening costs | B34: 50 | C34: Marketing, staffing, tech
A35: CapEx phasing: 2026 (% of total) | B35: 0.3
A36: CapEx phasing: 2027 (% of total) | B36: 0.5
A37: CapEx phasing: 2028 (% of total) | B37: 0.2
A38: Maintenance CapEx (% of revenue) | B38: 0.1 | C38: Annual reinvestment from 2029
A40: FINANCING
A41: Debt ratio (% of investment) | B41: 0.6
A42: Equity ratio (% of investment) | B42: 0.4
A43: Interest rate on debt | B43: 0.055 | C43: Blended rate
A44: Debt repayment start year | B44: 2029
...

Sheet Revenue
A1: Revenue Build-Up (€M)
D3: Revenue Build-Up (€M)
B4: 2026 | C4: 2027 | D4: 2028 | E4: 2029 | F4: 2030 | G4: 2031 | H4: 2032 | I4: 2033
A5: Visitors (millions) | B5: 0 | C5: 0 | D5: =Assumptions!B9*Assumptions!B10 -> 1.75 | E5: =Assumptions!B9*Assumptions!B11 -> 2.275 | F5: =Assumptions!B9*Assumptions!B12 -> 2.8 | G5: =Assumptions!B9*Assumptions!B13 -> 3.15 | H5: =Assumptions!B9*Assumptions!B14 -> 3.325 | I5: =Assumptions!B9*Assumptions!B15 -> 3.5
A6: Price escalation factor | B6: 1 | C6: 1 | D6: 1 | E6: =(1+Assumptions!B21)^1 -> 1.03 | F6: =(1+Assumptions!B21)^2 -> 1.0609 | G6: =(1+Assumptions!B21)^3 -> 1.092727 | H6: =(1+Assumptions!B21)^4 -> 1.1255088 | I6: =(1+Assumptions!B21)^5 -> 1.1592741
A8: Ticket Revenue | B8: =B5*Assumptions!B16*B6 -> 0 | C8: =C5*Assumptions!B16*C6 -> 0 | D8: =D5*Assumptions!B16*D6 -> 73.5 | E8: =E5*Assumptions!B16*E6 -> 98.4165 | F8: =F5*Assumptions!B16*F6 -> 124.76184 | G8: =G5*Assumptions!B16*G6 -> 144.56778 | H8: =H5*Assumptions!B16*H6 -> 157.17731 | I8: =I5*Assumptions!B16*I6 -> 170.41329
A9: In-Park Revenue (F&B, Merch) | B9: =B5*Assumptions!B17*B6 -> 0 | C9: =C5*Assumptions!B17*C6 -> 0 | D9: =D5*Assumptions!B17*D6 -> 49 | E9: =E5*Assumptions!B17*E6 -> 65.611 | F9: =F5*Assumptions!B17*F6 -> 83.17456 | G9: =G5*Assumptions!B17*G6 -> 96.378521 | H9: =H5*Assumptions!B17*H6 -> 104.78487 | I9: =I5*Assumptions!B17*I6 -> 113.60886
A10: Hotel Revenue | B10: 0 | C10: 0 | D10: =Assumptions!B19*Assumptions!B20*Assumptions!B18*365/1000000*D6 -> 61.685 | E10: =Assumptions!B19*Assumptions!B20*Assumptions!B18*365/1000000*E6 -> 63.53555 | F10: =Assumptions!B19*Assumptions!B20*Assumptions!B18*365/1000000*F6 -> 65.441616 | G10: =Assumptions!B19*Assumptions!B20*Assumptions!B18*365/1000000*G6 -> 67.404865 | H10: =Assumptions!B19*Assumptions!B20*Assumptions!B18*365/1000000*H6 -> 69.427011 | I10: =Assumptions!B19*Assumptions!B20*Assumptions!B18*365/1000000*I6 -> 71.509821
A12: Total Revenue | B12: =B8+B9+B10 -> 0 | C12: =C8+C9+C10 -> 0 | D12: =D8+D9+D10 -> 184.185 | E12: =E8+E9+E10 -> 227.56305 | F12: =F8+F9+F10 -> 273.37802 | G12: =G8+G9+G10 -> 308.35117 | H12: =H8+H9+H10 -> 331.38919 | I12: =I8+I9+I10 -> 355.53197

Sheet CapEx
A1: Capital Expenditure Schedule (€M)
D3: CapEx Schedule (€M)
B4: 2026 | C4: 2027 | D4: 2028 | E4: 2029 | F4: 2030 | G4: 2031 | H4: 2032 | I4: 2033
A5: INITIAL INVESTMENT
A6: Land acquisition | B6: =Assumptions!B30 -> 120 | C6: 0 | D6: 0 | E6: 0 | F6: 0 | G6: 0 | H6: 0 | I6: 0
A7: Construction & infrastructure | B7: =Assumptions!B31*Assumptions!B35 -> 105 | C7: =Assumptions!B31*Assumptions!B36 -> 175 | D7: =Assumptions!B31*Assumptions!B37 -> 70 | E7: 0 | F7: 0 | G7: 0 | H7: 0 | I7: 0
A8: Rides & attractions | B8: =Assumptions!B32*Assumptions!B35 -> 114 | C8: =Assumptions!B32*Assumptions!B36 -> 190 | D8: =Assumptions!B32*Assumptions!B37 -> 76 | E8: 0 | F8: 0 | G8: 0 | H8: 0 | I8: 0
A9: Hotels | B9: =Assumptions!B33*Assumptions!B35 -> 30 | C9: =Assumptions!B33*Assumptions!B36 -> 50 | D9: =Assumptions!B33*Assumptions!B37 -> 20 | E9: 0 | F9: 0 | G9: 0 | H9: 0 | I9: 0
A10: Pre-opening costs | B10: =Assumptions!B34*Assumptions!B35 -> 15 | C10: =Assumptions!B34*Assumptions!B36 -> 25 | D10: =Assumptions!B34*Assumptions!B37 -> 10 | E10: 0 | F10: 0 | G10: 0 | H10: 0 | I10: 0
A11: Total Initial CapEx | B11: =SUM(B6:B10) -> 384 | C11: =SUM(C6:C10) -> 440 | D11: =SUM(D6:D10) -> 176 | E11: =SUM(E6:E10) -> 0 | F11: =SUM(F6:F10) -> 0 | G11: =SUM(G6:G10) -> 0 | H11: =SUM(H6:H10) -> 0 | I11: =SUM(I6:I10) -> 0
A13: Maintenance CapEx | B13: 0 | C13: 0 | D13: 0 | E13: =Revenue!E12*Assumptions!B38 -> 22.756305 | F13: =Revenue!F12*Assumptions!B38 -> 27.337802 | G13: =Revenue!G12*Assumptions!B38 -> 30.835117 | H13: =Revenue!H12*Assumptions!B38 -> 33.138919 | I13: =Revenue!I12*Assumptions!B38 -> 35.553197
A15: TOTAL CAPEX | B15: =B11+B13 -> 384 | C15: =C11+C13 -> 440 | D15: =D11+D13 -> 176 | E15: =E11+E13 -> 22.756305 | F15: =F11+F13 -> 27.337802 | G15: =G11+G13 -> 30.835117 | H15: =H11+H13 -> 33.138919 | I15: =I11+I13 -> 35.553197
D17: Depreciation Schedule (€M)
B18: 2026 | C18: 2027 | D18: 2028 | E18: 2029 | F18: 2030 | G18: 2031 | H18: 2032 | I18: 2033
A19: Depreciable base (excl. land) | B19: =Assumptions!B29-Assumptions!B30 -> 880
A20: Annual depreciation (initial) | B20: =B19/Assumptions!B54 -> 44
A22: Depreciation — initial assets | B22: 0 | C22: 0 | D22: =$B$20 -> 44 | E22: =$B$20 -> 44 | F22: =$B$20 -> 44 | G22: =$B$20 -> 44 | H22: =$B$20 -> 44 | I22: =$B$20 -> 44
A23: Depreciation — maintenance CapEx | B23: 0 | C23: 0 | D23: 0 | E23: 0 | F23: =E23+E13/Assumptions!B54 -> 1.1378153 | G23: =F23+F13/Assumptions!B54 -> 2.5047053 | H23: =G23+G13/Assumptions!B54 -> 4.0464612 | I23: =H23+H13/Assumptions!B54 -> 5.7034071
A24: Total Depreciation | B24: =B22+B23 -> 0 | C24: =C22+C23 -> 0 | D24: =D22+D23 -> 44 | E24: =E22+E23 -> 44 | F24: =F22+F23 -> 45.137815 | G24: =G22+G23 -> 46.504705 | H24: =H22+H23 -> 48.046461 | I24: =I22+I23 -> 49.703407
D26: PP&E Schedule (€M)
B27: 2026 | C27: 2027 | D27: 2028 | E27: 2029 | F27: 2030 | G27: 2031 | H27: 2032 | I27: 2033
A28: Beginning gross PP&E | B28: 0 | C28: =B30 -> 384 | D28: =C30 -> 824 | E28: =D30 -> 1000 | F28: =E30 -> 1022.7563 | G28: =F30 -> 1050.0941 | H28: =G30 -> 1080.9292 | I28: =H30 -> 1114.0681
A29: + CapEx additions | B29: =B15 -> 384 | C29: =C15 -> 440 | D29: =D15 -> 176 | E29: =E15 -> 22.756305 | F29: =F15 -> 27.337802 | G29: =G15 -> 30.835117 | H29: =H15 -> 33.138919 | I29: =I15 -> 35.553197
A30: Ending gross PP&E | B30: =B28+B29 -> 384 | C30: =C28+C29 -> 824 | D30: =D28+D29 -> 1000 | E30: =E28+E29 -> 1022.7563 | F30: =F28+F29 -> 1050.0941 | G30: =G28+G29 -> 1080.9292 | H30: =H28+H29 -> 1114.0681 | I30: =I28+I29 -> 1149.6213
A32: Beginning accum. depreciation | B32: 0 | C32: =B33 -> 0 | D32: =C33 -> 0 | E32: =D33 -> 44 | F32: =E33 -> 88 | G32: =F33 -> 133.13782 | H32: =G33 -> 179.64252 | I32: =H33 -> 227.68898
A33: Ending accum. depreciation | B33: =B32+B24 -> 0 | C33: =C32+C24 -> 0 | D33: =D32+D24 -> 44 | E33: =E32+E24 -> 88 | F33: =F32+F24 -> 133.13782 | G33: =G32+G24 -> 179.64252 | H33: =H32+H24 -> 227.68898 | I33: =I32+I24 -> 277.39239
A35: Net PP&E | B35: =B30-B33 -> 384 | C35: =C30-C33 -> 824 | D35: =D30-D33 -> 956 | E35: =E30-E33 -> 934.7563 | F35: =F30-F33 -> 916.95629 | G35: =G30-G33 -> 901.2867 | H35: =H30-H33 -> 886.37916 | I35: =I30-I33 -> 872.22895

Sheet Debt
A1: Debt Schedule (€M)
D3: Debt Schedule (€M)
B4: 2026 | C4: 2027 | D4: 2028 | E4: 2029 | F4: 2030 | G4: 2031 | H4: 2032 | I4: 2033
A5: Total debt amount | B5: =Assumptions!B29*Assumptions!B41 -> 600
A6: Annual repayment amount | B6: =B5/Assumptions!B45 -> 40
A8: Beginning balance | B8: 0 | C8: =B12 -> 230.4 | D8: =C12 -> 494.4 | E8: =D12 -> 600 | F8: =E12 -> 560 | G8: =F12 -> 520 | H8: =G12 -> 480 | I8: =H12 -> 440
A9: + Drawdowns | B9: =CapEx!B15*Assumptions!B41 -> 230.4 | C9: =CapEx!C15*Assumptions!B41 -> 264 | D9: =CapEx!D11*Assumptions!B41 -> 105.6 | E9: 0 | F9: 0 | G9: 0 | H9: 0 | I9: 0
A10: - Principal repayment | B10: 0 | C10: 0 | D10: 0 | E10: =$B$6 -> 40 | F10: =$B$6 -> 40 | G10: =$B$6 -> 40 | H10: =$B$6 -> 40 | I10: =$B$6 -> 40
A12: Ending balance | B12: =B8+B9-B10 -> 230.4 | C12: =C8+C9-C10 -> 494.4 | D12: =D8+D9-D10 -> 600 | E12: =E8+E9-E10 -> 560 | F12: =F8+F9-F10 -> 520 | G12: =G8+G9-G10 -> 480 | H12: =H8+H9-H10 -> 440 | I12: =I8+I9-I10 -> 400
A14: Interest expense | B14: =B8*Assumptions!B43 -> 0 | C14: =C8*Assumptions!B43 -> 12.672 | D14: =D8*Assumptions!B43 -> 27.192 | E14: =E8*Assumptions!B43 -> 33 | F14: =F8*Assumptions!B43 -> 30.8 | G14: =G8*Assumptions!B43 -> 28.6 | H14: =H8*Assumptions!B43 -> 26.4 | I14: =I8*Assumptions!B43 -> 24.2
A16: Current portion of LTD | B16: 0 | C16: 0 | D16: =MIN($B$6,D12) -> 40 | E16: =MIN($B$6,E12) -> 40 | F16: =MIN($B$6,F12) -> 40 | G16: =MIN($B$6,G12) -> 40 | H16: =MIN($B$6,H12) -> 40 | I16: =MIN($B$6,I12) -> 40
A17: Long-term portion | B17: =B12-B16 -> 230.4 | C17: =C12-C16 -> 494.4 | D17: =D12-D16 -> 560 | E17: =E12-E16 -> 520 | F17: =F12-F16 -> 480 | G17: =G12-G16 -> 440 | H17: =H12-H16 -> 400 | I17: =I12-I16 -> 360

Sheet WorkingCapital
A1: Working Capital Schedule (€M)
D3: Working Capital (€M)
B4: 2026 | C4: 2027 | D4: 2028 | E4: 2029 | F4: 2030 | G4: 2031 | H4: 2032 | I4: 2033
A5: Revenue (reference) | B5: =Revenue!B12 -> 0 | C5: =Revenue!C12 -> 0 | D5: =Revenue!D12 -> 184.185 | E5: =Revenue!E12 -> 227.56305 | F5: =Revenue!F12 -> 273.37802 | G5: =Revenue!G12 -> 308.35117 | H5: =Revenue!H12 -> 331.38919 | I5: =Revenue!I12 -> 355.53197
A6: COGS (reference) | B6: =B5*Assumptions!B24 -> 0 | C6: =C5*Assumptions!B24 -> 0 | D6: =D5*Assumptions!B24 -> 55.2555 | E6: =E5*Assumptions!B24 -> 68.268915 | F6: =F5*Assumptions!B24 -> 82.013405 | G6: =G5*Assumptions!B24 -> 92.505351 | H6: =H5*Assumptions!B24 -> 99.416756 | I6: =I5*Assumptions!B24 -> 106.65959
A8: Accounts Receivable | B8: =B5*Assumptions!B48/365 -> 0 | C8: =C5*Assumptions!B48/365 -> 0 | D8: =D5*Assumptions!B48/365 -> 7.5692466 | E8: =E5*Assumptions!B48/365 -> 9.3519062 | F8: =F5*Assumptions!B48/365 -> 11.234713 | G8: =G5*Assumptions!B48/365 -> 12.671966 | H8: =H5*Assumptions!B48/365 -> 13.618734 | I8: =I5*Assumptions!B48/365 -> 14.610903
A9: Inventory | B9: =B6*Assumptions!B49/365 -> 0 | C9: =C6*Assumptions!B49/365 -> 0 | D9: =D6*Assumptions!B49/365 -> 4.5415479 | E9: =E6*Assumptions!B49/365 -> 5.6111437 | F9: =F6*Assumptions!B49/365 -> 6.7408278 | G9: =G6*Assumptions!B49/365 -> 7.6031795 | H9: =H6*Assumptions!B49/365 -> 8.1712402 | I9: =I6*Assumptions!B49/365 -> 8.7665417
A10: Accounts Payable | B10: =B6*Assumptions!B50/365 -> 0 | C10: =C6*Assumptions!B50/365 -> 0 | D10: =D6*Assumptions!B50/365 -> 6.8123219 | E10: =E6*Assumptions!B50/365 -> 8.4167155 | F10: =F6*Assumptions!B50/365 -> 10.111242 | G10: =G6*Assumptions!B50/365 -> 11.404769 | H10: =H6*Assumptions!B50/365 -> 12.25686 | I10: =I6*Assumptions!B50/365 -> 13.149813
A12: Net Working Capital | B12: =B8+B9-B10 -> 0 | C12: =C8+C9-C10 -> 0 | D12: =D8+D9-D10 -> 5.2984726 | E12: =E8+E9-E10 -> 6.5463343 | F12: =F8+F9-F10 -> 7.8642991 | G12: =G8+G9-G10 -> 8.8703761 | H12: =H8+H9-H10 -> 9.5331136 | I12: =I8+I9-I10 -> 10.227632
A14: Change in Working Capital | B14: =B12 -> 0 | C14: =C12-B12 -> 0 | D14: =D12-C12 -> 5.2984726 | E14: =E12-D12 -> 1.2478617 | F14: =F12-E12 -> 1.3179648 | G14: =G12-F12 -> 1.006077 | H14: =H12-G12 -> 0.6627375 | I14: =I12-H12 -> 0.69451842

Sheet HR
A1: Human Resources Plan (€M)
D3: Headcount & Labor Cost (€M)
B4: 2026 | C4: 2027 | D4: 2028 | E4: 2029 | F4: 2030 | G4: 2031 | H4: 2032 | I4: 2033
A5: HEADCOUNT BY DEPARTMENT
A6: Operations & ride staff | B6: 0 | C6: 50 | D6: 800 | E6: 900 | F6: 1000 | G6: 1050 | H6: 1100 | I6: 1100
A7: F&B staff | B7: 0 | C7: 30 | D7: 400 | E7: 450 | F7: 500 | G7: 530 | H7: 550 | I7: 550
A8: Hotel staff | B8: 0 | C8: 20 | D8: 350 | E8: 380 | F8: 400 | G8: 420 | H8: 440 | I8: 440
A9: Maintenance & technical | B9: 0 | C9: 30 | D9: 200 | E9: 220 | F9: 240 | G9: 250 | H9: 260 | I9: 260
A10: Security | B10: 0 | C10: 10 | D10: 150 | E10: 160 | F10: 170 | G10: 180 | H10: 190 | I10: 190
A11: Marketing & sales | B11: 0 | C11: 15 | D11: 80 | E11: 85 | F11: 90 | G11: 95 | H11: 100 | I11: 100
A12: Administration & management | B12: 0 | C12: 20 | D12: 120 | E12: 125 | F12: 130 | G12: 135 | H12: 140 | I12: 140
A13: Total Headcount | B13: =SUM(B6:B12) -> 0 | C13: =SUM(C6:C12) -> 175 | D13: =SUM(D6:D12) -> 2100 | E13: =SUM(E6:E12) -> 2320 | F13: =SUM(F6:F12) -> 2530 | G13: =SUM(G6:G12) -> 2660 | H13: =SUM(H6:H12) -> 2780 | I13: =SUM(I6:I12) -> 2780
A15: COST PER EMPLOYEE (€M)
A16: Avg employer cost per employee (€/year) | B16: 10800 | C16: 10800 | D16: 10800 | E16: 10800 | F16: 10800 | G16: 10800 | H16: 10800 | I16: 10800
A18: Total Labor Cost (€M) | B18: =B13*B16/1000000 -> 0 | C18: =C13*C16/1000000 -> 1.89 | D18: =D13*D16/1000000 -> 22.68 | E18: =E13*E16/1000000 -> 25.056 | F18: =F13*F16/1000000 -> 27.324 | G18: =G13*G16/1000000 -> 28.728 | H18: =H13*H16/1000000 -> 30.024 | I18: =I13*I16/1000000 -> 30.024

Sheet Marketing
A1: Marketing Cost Plan (€M)
D3: Marketing Budget (€M)
B4: 2026 | C4: 2027 | D4: 2028 | E4: 2029 | F4: 2030 | G4: 2031 | H4: 2032 | I4: 2033
A5: Pre-launch brand campaign | B5: 3 | C5: 8 | D5: 5 | E5: 0 | F5: 0 | G5: 0 | H5: 0 | I5: 0
A6: Digital marketing | B6: 1 | C6: 2 | D6: 4 | E6: 5 | F6: 5 | G6: 5 | H6: 6 | I6: 6
A7: Traditional media (TV, print, OOH) | B7: 0 | C7: 2 | D7: 5 | E7: 4 | F7: 3 | G7: 3 | H7: 3 | I7: 3
A8: Partnerships & travel agencies | B8: 0 | C8: 1 | D8: 3 | E8: 3 | F8: 3 | G8: 3 | H8: 3 | I8: 3
A9: Events & PR | B9: 0 | C9: 1 | D9: 3 | E9: 2 | F9: 2 | G9: 2 | H9: 2 | I9: 2
A10: CRM & loyalty programs | B10: 0 | C10: 0 | D10: 1 | E10: 2 | F10: 2 | G10: 2 | H10: 2 | I10: 2
A11: Total Marketing Cost (€M) | B11: =SUM(B5:B10) -> 4 | C11: =SUM(C5:C10) -> 14 | D11: =SUM(D5:D10) -> 21 | E11: =SUM(E5:E10) -> 16 | F11: =SUM(F5:F10) -> 15 | G11: =SUM(G5:G10) -> 15 | H11: =SUM(H5:H10) -> 16 | I11: =SUM(I5:I10) -> 16
A13: Marketing as % of Revenue | D13: =D11/Revenue!D12 -> 0.1140158 | E13: =E11/Revenue!E12 -> 0.070310184 | F13: =F11/Revenue!F12 -> 0.054869079 | G13: =G11/Revenue!G12 -> 0.048645835 | H13: =H11/Revenue!H12 -> 0.0482816 | I13: =I11/Revenue!I12 -> 0.045002985

Sheet Statements
A1: Pro Forma Financial Statements (€M)
D3: Income Statement (€M)
B4: 2026 | C4: 2027 | D4: 2028 | E4: 2029 | F4: 2030 | G4: 2031 | H4: 2032 | I4: 2033
A5: Revenue | B5: =Revenue!B12 -> 0 | C5: =Revenue!C12 -> 0 | D5: =Revenue!D12 -> 184.185 | E5: =Revenue!E12 -> 227.56305 | F5: =Revenue!F12 -> 273.37802 | G5: =Revenue!G12 -> 308.35117 | H5: =Revenue!H12 -> 331.38919 | I5: =Revenue!I12 -> 355.53197
A6: COGS | B6: =-B5*Assumptions!B24 -> 0 | C6: =-C5*Assumptions!B24 -> 0 | D6: =-D5*Assumptions!B24 -> -55.2555 | E6: =-E5*Assumptions!B24 -> -68.268915 | F6: =-F5*Assumptions!B24 -> -82.013405 | G6: =-G5*Assumptions!B24 -> -92.505351 | H6: =-H5*Assumptions!B24 -> -99.416756 | I6: =-I5*Assumptions!B24 -> -106.65959
A7: Gross Profit | B7: =B5+B6 -> 0 | C7: =C5+C6 -> 0 | D7: =D5+D6 -> 128.9295 | E7: =E5+E6 -> 159.29414 | F7: =F5+F6 -> 191.36461 | G7: =G5+G6 -> 215.84582 | H7: =H5+H6 -> 231.97243 | I7: =I5+I6 -> 248.87238
A8: Operating expenses | B8: 0 | C8: 0 | D8: =-D5*(Assumptions!B25-Assumptions!B26*0) -> -46.04625 | E8: =-E5*(Assumptions!B25-Assumptions!B26*1) -> -55.752947 | F8: =-F5*(Assumptions!B25-Assumptions!B26*2) -> -65.610724 | G8: =-G5*(Assumptions!B25-Assumptions!B26*3) -> -72.462525 | H8: =-H5*(Assumptions!B25-Assumptions!B26*4) -> -76.219513 | I8: =-I5*(Assumptions!B25-Assumptions!B26*5) -> -79.994693
A9: Depreciation & amortization | B9: =-CapEx!B24 -> 0 | C9: =-CapEx!C24 -> 0 | D9: =-CapEx!D24 -> -44 | E9: =-CapEx!E24 -> -44 | F9: =-CapEx!F24 -> -45.137815 | G9: =-CapEx!G24 -> -46.504705 | H9: =-CapEx!H24 -> -48.046461 | I9: =-CapEx!I24 -> -49.703407
A10: Labor costs | B10: 0 | C10: 0 | D10: =-HR!D18 -> -22.68 | E10: =-HR!E18 -> -25.056 | F10: =-HR!F18 -> -27.324 | G10: =-HR!G18 -> -28.728 | H10: =-HR!H18 -> -30.024 | I10: =-HR!I18 -> -30.024
A11: Marketing costs | B11: 0 | C11: 0 | D11: =-Marketing!D11 -> -21 | E11: =-Marketing!E11 -> -16 | F11: =-Marketing!F11 -> -15 | G11: =-Marketing!G11 -> -15 | H11: =-Marketing!H11 -> -16 | I11: =-Marketing!I11 -> -16
A12: Operating Income (EBIT) | B12: =B7+B8+B9+B10+B11 -> 0 | C12: =C7+C8+C9+C10+C11 -> 0 | D12: =D7+D8+D9+D10+D11 -> -4.79675 | E12: =E7+E8+E9+E10+E11 -> 18.485188 | F12: =F7+F8+F9+F10+F11 -> 38.292072 | G12: =G7+G8+G9+G10+G11 -> 53.150588 | H12: =H7+H8+H9+H10+H11 -> 61.682456 | I12: =I7+I8+I9+I10+I11 -> 73.150278
A13: Interest expenses | B13: =-Debt!B14 -> 0 | C13: =-Debt!C14 -> -12.672 | D13: =-Debt!D14 -> -27.192 | E13: =-Debt!E14 -> -33 | F13: =-Debt!F14 -> -30.8 | G13: =-Debt!G14 -> -28.6 | H13: =-Debt!H14 -> -26.4 | I13: =-Debt!I14 -> -24.2
A14: Pretax Income | B14: =B12+B13 -> 0 | C14: =C12+C13 -> -12.672 | D14: =D12+D13 -> -31.98875 | E14: =E12+E13 -> -14.514812 | F14: =F12+F13 -> 7.4920723 | G14: =G12+G13 -> 24.550588 | H14: =H12+H13 -> 35.282456 | I14: =I12+I13 -> 48.950278
A15: Income Tax Expense | B15: =-MAX(B14,0)*Assumptions!B53 -> 0 | C15: =-MAX(C14,0)*Assumptions!B53 -> 0 | D15: =-MAX(D14,0)*Assumptions!B53 -> 0 | E15: =-MAX(E14,0)*Assumptions!B53 -> 0 | F15: =-MAX(F14,0)*Assumptions!B53 -> -1.8730181 | G15: =-MAX(G14,0)*Assumptions!B53 -> -6.137647 | H15: =-MAX(H14,0)*Assumptions!B53 -> -8.8206141 | I15: =-MAX(I14,0)*Assumptions!B53 -> -12.23757
A16: Net Income | B16: =B14+B15 -> 0 | C16: =C14+C15 -> -12.672 | D16: =D14+D15 -> -31.98875 | E16: =E14+E15 -> -14.514812 | F16: =F14+F15 -> 5.6190543 | G16: =G14+G15 -> 18.412941 | H16: =H14+H15 -> 26.461842 | I16: =I14+I15 -> 36.712709
D19: Balance Sheet (€M)
B20: 2026 | C20: 2027 | D20: 2028 | E20: 2029 | F20: 2030 | G20: 2031 | H20: 2032 | I20: 2033
A21: Cash | B21: =B69 -> 80 | C21: =C69 -> 67.328 | D21: =D69 -> 74.040777 | E21: =E69 -> 39.521798 | F21: =F69 -> 21.622902 | G21: =G69 -> 14.699354 | H21: =H69 -> 15.406001 | I21: =I69 -> 25.574402
A22: Accounts Receivable | B22: =WorkingCapital!B8 -> 0 | C22: =WorkingCapital!C8 -> 0 | D22: =WorkingCapital!D8 -> 7.5692466 | E22: =WorkingCapital!E8 -> 9.3519062 | F22: =WorkingCapital!F8 -> 11.234713 | G22: =WorkingCapital!G8 -> 12.671966 | H22: =WorkingCapital!H8 -> 13.618734 | I22: =WorkingCapital!I8 -> 14.610903
A23: Inventory | B23: =WorkingCapital!B9 -> 0 | C23: =WorkingCapital!C9 -> 0 | D23: =WorkingCapital!D9 -> 4.5415479 | E23: =WorkingCapital!E9 -> 5.6111437 | F23: =WorkingCapital!F9 -> 6.7408278 | G23: =WorkingCapital!G9 -> 7.6031795 | H23: =WorkingCapital!H9 -> 8.1712402 | I23: =WorkingCapital!I9 -> 8.7665417
A24: Total Current Assets | B24: =B21+B22+B23 -> 80 | C24: =C21+C22+C23 -> 67.328 | D24: =D21+D22+D23 -> 86.151572 | E24: =E21+E22+E23 -> 54.484848 | F24: =F21+F22+F23 -> 39.598442 | G24: =G21+G22+G23 -> 34.974499 | H24: =H21+H22+H23 -> 37.195975 | I24: =I21+I22+I23 -> 48.951847
A26: Net PP&E | B26: =CapEx!B35 -> 384 | C26: =CapEx!C35 -> 824 | D26: =CapEx!D35 -> 956 | E26: =CapEx!E35 -> 934.7563 | F26: =CapEx!F35 -> 916.95629 | G26: =CapEx!G35 -> 901.2867 | H26: =CapEx!H35 -> 886.37916 | I26: =CapEx!I35 -> 872.22895
A27: Other Non-Current Assets | B27: 0 | C27: 0 | D27: 0 | E27: 0 | F27: 0 | G27: 0 | H27: 0 | I27: 0
A28: Total Non-Current Assets | B28: =B26+B27 -> 384 | C28: =C26+C27 -> 824 | D28: =D26+D27 -> 956 | E28: =E26+E27 -> 934.7563 | F28: =F26+F27 -> 916.95629 | G28: =G26+G27 -> 901.2867 | H28: =H26+H27 -> 886.37916 | I28: =I26+I27 -> 872.22895
A30: TOTAL ASSETS | B30: =B24+B28 -> 464 | C30: =C24+C28 -> 891.328 | D30: =D24+D28 -> 1042.1516 | E30: =E24+E28 -> 989.24115 | F30: =F24+F28 -> 956.55473 | G30: =G24+G28 -> 936.2612 | H30: =H24+H28 -> 923.57514 | I30: =I24+I28 -> 921.1808
A32: Accounts Payable | B32: =WorkingCapital!B10 -> 0 | C32: =WorkingCapital!C10 -> 0 | D32: =WorkingCapital!D10 -> 6.8123219 | E32: =WorkingCapital!E10 -> 8.4167155 | F32: =WorkingCapital!F10 -> 10.111242 | G32: =WorkingCapital!G10 -> 11.404769 | H32: =WorkingCapital!H10 -> 12.25686 | I32: =WorkingCapital!I10 -> 13.149813
A33: Accrued Liabilities | B33: 0 | C33: 0 | D33: 0 | E33: 0 | F33: 0 | G33: 0 | H33: 0 | I33: 0
A34: Current Portion of LTD | B34: =Debt!B16 -> 0 | C34: =Debt!C16 -> 0 | D34: =Debt!D16 -> 40 | E34: =Debt!E16 -> 40 | F34: =Debt!F16 -> 40 | G34: =Debt!G16 -> 40 | H34: =Debt!H16 -> 40 | I34: =Debt!I16 -> 40
A35: Total Current Liabilities | B35: =B32+B33+B34 -> 0 | C35: =C32+C33+C34 -> 0 | D35: =D32+D33+D34 -> 46.812322 | E35: =E32+E33+E34 -> 48.416716 | F35: =F32+F33+F34 -> 50.111242 | G35: =G32+G33+G34 -> 51.404769 | H35: =H32+H33+H34 -> 52.25686 | I35: =I32+I33+I34 -> 53.149813
A37: Long-Term Debt | B37: =Debt!B17 -> 230.4 | C37: =Debt!C17 -> 494.4 | D37: =Debt!D17 -> 560 | E37: =Debt!E17 -> 520 | F37: =Debt!F17 -> 480 | G37: =Debt!G17 -> 440 | H37: =Debt!H17 -> 400 | I37: =Debt!I17 -> 360
A38: Other Non-Current Liabilities | B38: 0 | C38: 0 | D38: 0 | E38: 0 | F38: 0 | G38: 0 | H38: 0 | I38: 0
A39: Total Non-Current Liabilities | B39: =B37+B38 -> 230.4 | C39: =C37+C38 -> 494.4 | D39: =D37+D38 -> 560 | E39: =E37+E38 -> 520 | F39: =F37+F38 -> 480 | G39: =G37+G38 -> 440 | H39: =H37+H38 -> 400 | I39: =I37+I38 -> 360
A41: TOTAL LIABILITIES | B41: =B35+B39 -> 230.4 | C41: =C35+C39 -> 494.4 | D41: =D35+D39 -> 606.81232 | E41: =E35+E39 -> 568.41672 | F41: =F35+F39 -> 530.11124 | G41: =G35+G39 -> 491.40477 | H41: =H35+H39 -> 452.25686 | I41: =I35+I39 -> 413.14981
A43: Share Capital | B43: =CapEx!B15*Assumptions!B42+Assumptions!B61 -> 233.6 | C43: =B43+CapEx!C15*Assumptions!B42 -> 409.6 | D43: =C43+CapEx!D11*Assumptions!B42 -> 480 | E43: =D43 -> 480 | F43: =E43 -> 480 | G43: =F43 -> 480 | H43: =G43 -> 480 | I43: =H43 -> 480
A44: Retained Earnings | B44: =B16 -> 0 | C44: =B44+C16 -> -12.672 | D44: =C44+D16 -> -44.66075 | E44: =D44+E16 -> -59.175562 | F44: =E44+F16 -> -53.556508 | G44: =F44+G16 -> -35.143567 | H44: =G44+H16 -> -8.6817246 | I44: =H44+I16 -> 28.030984
A45: Total Equity | B45: =B43+B44 -> 233.6 | C45: =C43+C44 -> 396.928 | D45: =D43+D44 -> 435.33925 | E45: =E43+E44 -> 420.82444 | F45: =F43+F44 -> 426.44349 | G45: =G43+G44 -> 444.85643 | H45: =H43+H44 -> 471.31828 | I45: =I43+I44 -> 508.03098
A47: TOTAL LIABILITIES & EQUITY | B47: =B41+B45 -> 464 | C47: =C41+C45 -> 891.328 | D47: =D41+D45 -> 1042.1516 | E47: =E41+E45 -> 989.24115 | F47: =F41+F45 -> 956.55473 | G47: =G41+G45 -> 936.2612 | H47: =H41+H45 -> 923.57514 | I47: =I41+I45 -> 921.1808
D50: Cash Flow Statement (€M)
B51: 2026 | C51: 2027 | D51: 2028 | E51: 2029 | F51: 2030 | G51: 2031 | H51: 2032 | I51: 2033
A52: Net Income | B52: =B16 -> 0 | C52: =C16 -> -12.672 | D52: =D16 -> -31.98875 | E52: =E16 -> -14.514812 | F52: =F16 -> 5.6190543 | G52: =G16 -> 18.412941 | H52: =H16 -> 26.461842 | I52: =I16 -> 36.712709
...

Sheet InvestCriteria
A1: Investment Criteria
D3: Free Cash Flow & Valuation (€M)
B4: 2026 | C4: 2027 | D4: 2028 | E4: 2029 | F4: 2030 | G4: 2031 | H4: 2032 | I4: 2033
A5: EBIT | B5: =Statements!B12 -> 0 | C5: =Statements!C12 -> 0 | D5: =Statements!D12 -> -4.79675 | E5: =Statements!E12 -> 18.485188 | F5: =Statements!F12 -> 38.292072 | G5: =Statements!G12 -> 53.150588 | H5: =Statements!H12 -> 61.682456 | I5: =Statements!I12 -> 73.150278
A6: + Depreciation | B6: =CapEx!B24 -> 0 | C6: =CapEx!C24 -> 0 | D6: =CapEx!D24 -> 44 | E6: =CapEx!E24 -> 44 | F6: =CapEx!F24 -> 45.137815 | G6: =CapEx!G24 -> 46.504705 | H6: =CapEx!H24 -> 48.046461 | I6: =CapEx!I24 -> 49.703407
A7: - Taxes on EBIT | B7: =-MAX(B5,0)*Assumptions!B53 -> 0 | C7: =-MAX(C5,0)*Assumptions!B53 -> 0 | D7: =-MAX(D5,0)*Assumptions!B53 -> 0 | E7: =-MAX(E5,0)*Assumptions!B53 -> -4.6212969 | F7: =-MAX(F5,0)*Assumptions!B53 -> -9.5730181 | G7: =-MAX(G5,0)*Assumptions!B53 -> -13.287647 | H7: =-MAX(H5,0)*Assumptions!B53 -> -15.420614 | I7: =-MAX(I5,0)*Assumptions!B53 -> -18.28757
A8: - CapEx | B8: =-CapEx!B15 -> -384 | C8: =-CapEx!C15 -> -440 | D8: =-CapEx!D15 -> -176 | E8: =-CapEx!E15 -> -22.756305 | F8: =-CapEx!F15 -> -27.337802 | G8: =-CapEx!G15 -> -30.835117 | H8: =-CapEx!H15 -> -33.138919 | I8: =-CapEx!I15 -> -35.553197
A9: - Change in Working Capital | B9: =-WorkingCapital!B14 -> 0 | C9: =-WorkingCapital!C14 -> 0 | D9: =-WorkingCapital!D14 -> -5.2984726 | E9: =-WorkingCapital!E14 -> -1.2478617 | F9: =-WorkingCapital!F14 -> -1.3179648 | G9: =-WorkingCapital!G14 -> -1.006077 | H9: =-WorkingCapital!H14 -> -0.6627375 | I9: =-WorkingCapital!I14 -> -0.69451842
A10: Free Cash Flow to Firm (FCFF) | B10: =B5+B6+B7+B8+B9 -> -384 | C10: =C5+C6+C7+C8+C9 -> -440 | D10: =D5+D6+D7+D8+D9 -> -142.09522 | E10: =E5+E6+E7+E8+E9 -> 33.859724 | F10: =F5+F6+F7+F8+F9 -> 45.201103 | G10: =G5+G6+G7+G8+G9 -> 54.526453 | H10: =H5+H6+H7+H8+H9 -> 60.506647 | I10: =I5+I6+I7+I8+I9 -> 68.318401
A12: FCFF | B12: =B10 -> -384 | C12: =C10 -> -440 | D12: =D10 -> -142.09522 | E12: =E10 -> 33.859724 | F12: =F10 -> 45.201103 | G12: =G10 -> 54.526453 | H12: =H10 -> 60.506647 | I12: =I10 -> 68.318401
A13: + Debt drawdowns | B13: =Debt!B9 -> 230.4 | C13: =Debt!C9 -> 264 | D13: =Debt!D9 -> 105.6 | E13: =Debt!E9 -> 0 | F13: =Debt!F9 -> 0 | G13: =Debt!G9 -> 0 | H13: =Debt!H9 -> 0 | I13: =Debt!I9 -> 0
A14: - Principal repayment | B14: =-Debt!B10 -> 0 | C14: =-Debt!C10 -> 0 | D14: =-Debt!D10 -> 0 | E14: =-Debt!E10 -> -40 | F14: =-Debt!F10 -> -40 | G14: =-Debt!G10 -> -40 | H14: =-Debt!H10 -> -40 | I14: =-Debt!I10 -> -40
A15: - Interest (after tax) | B15: =-Debt!B14*(1-Assumptions!B53) -> 0 | C15: =-Debt!C14*(1-Assumptions!B53) -> -9.504 | D15: =-Debt!D14*(1-Assumptions!B53) -> -20.394 | E15: =-Debt!E14*(1-Assumptions!B53) -> -24.75 | F15: =-Debt!F14*(1-Assumptions!B53) -> -23.1 | G15: =-Debt!G14*(1-Assumptions!B53) -> -21.45 | H15: =-Debt!H14*(1-Assumptions!B53) -> -19.8 | I15: =-Debt!I14*(1-Assumptions!B53) -> -18.15
A16: Free Cash Flow to Equity (FCFE) | B16: =B12+B13+B14+B15 -> -153.6 | C16: =C12+C13+C14+C15 -> -185.504 | D16: =D12+D13+D14+D15 -> -56.889223 | E16: =E12+E13+E14+E15 -> -30.890276 | F16: =F12+F13+F14+F15 -> -17.898897 | G16: =G12+G13+G14+G15 -> -6.9235475 | H16: =H12+H13+H14+H15 -> 0.70664737 | I16: =I12+I13+I14+I15 -> 10.168401
D18: Investment Metrics
A19: WACC | B19: =Assumptions!B60 -> 0.07275
A20: NPV of FCFF (€M) | B20: =NPV(B19,C10:I10)+B10 -> -736.20723
A21: IRR of FCFF | B21: =IFERROR(IRR(B10:I10),"N/A - extend projection") -> N/A - extend projection
A22: NPV of FCFE (€M) | B22: =NPV(Assumptions!B58,C16:I16)+B16 -> -396.9134
A23: IRR of FCFE | B23: =IFERROR(IRR(B16:I16),"N/A - extend projection") -> N/A - extend projection
A25: TERMINAL VALUE (Gordon Growth)
A26: Long-term growth rate | B26: 0.02
A27: Terminal FCFF | B27: =I10*(1+B26) -> 69.684769
A28: Terminal Value (€M) | B28: =B27/(B19-B26) -> 1321.0383
A29: PV of Terminal Value (€M) | B29: =B28/(1+B19)^8 -> 753.22931
A30: Total Project Value (NPV + PV of TV) | B30: =B20+B29 -> 17.022085

Sheet Scenarios
A1: Scenario Analysis
D3: Three Scenarios
B4: Pessimistic | C4: Base | D4: Optimistic
A5: Target visitors (M) | B5: 2.5 | C5: 3.5 | D5: 5
A6: Average ticket price (€) | B6: 35 | C6: 42 | D6: 48
A7: Per capita in-park spend (€) | B7: 22 | C7: 28 | D7: 35
A8: Hotel occupancy rate | B8: 0.55 | C8: 0.65 | D8: 0.75
A9: COGS as % of revenue | B9: 0.33 | C9: 0.3 | D9: 0.27
A10: OpEx as % of revenue | B10: 0.28 | C10: 0.25 | D10: 0.22
A11: Interest rate | B11: 0.065 | C11: 0.055 | D11: 0.045
A13: RESULTS (manual entry after running each scenario)
A14: NPV of FCFF (€M)
A15: IRR of FCFF
A16: Payback Period (years)
A17: Total Project Value (€M)
A20: SENSITIVITY ANALYSIS
A21: Impact on NPV when variable changes by:
B22: -20% | C22: -10% | D22: Base | E22: +10% | F22: +20%
A23: Visitor volume
A24: Ticket price
A25: COGS %
A26: Interest rate
